Workbook
Name Barranquilla: Formato!$J$61:$J$63
Name BCEMPRESARIAL: Formato!$N$61:$N$64
Name PLANTA1: Formato!$N$61:$N$64
Name PLANTA2: Formato!$N$65:$N$67
Name PLANTA3: Formato!$N$79:$N$80
Name PLANTA4: Formato!$N$68:$N$78

Sheet Formato
E2: FORMATO DE REQUISICIÓN Y DEVOLUCIÓN DE MATERIALES | P2: VERSIÓN: 52
P6: PÁGINA: 1 de 1
B11: Ciudad Origen Movimiento | E11: Villavicencio | Y11: Doc. Referencia
B14: Clase de movimiento | K14: Fecha de Solicitud | L14: 46294
L15: 3
K16: Consecutivo | M16: 1 | AG16: ZZ.CO11.250130.31
P17: Usar solo en caso de traslado | W17: Solo en caso de proyectos | AG17: observacionZZ.CO11.250130.31
A18: COD RESERVA | B18: Código artículo | C18: Cantidad | D18: Und | E18: Descripción | M18: Planta de Origen | N18: Storage Location Origen | O18: No de Serial | P18: Planta de Destino | V18: Storage Location Destino | W18: No WBS/Proyecto | AF18: Entrada | AG18: OBSERVACION | AJ18: Planta | AK18: Opcion
D19: =IF(ISERROR(VLOOKUP(B19,$A$61:$C$30467,3,FALSE))=TRUE," ",VLOOKUP(B19,$A$61:$C$30467,3,FALSE)) | E19: =IF(ISERROR(VLOOKUP(B19,$A$61:$C$30000,2,FALSE))=TRUE," ",VLOOKUP(B19,$A$61:$C$30000,2,FALSE)) | M19: CO29 LN Villavicencio | Z19: {=_xlfn._xlws.FILTER(TablaOpciones[Opcion],TablaOpciones[Planta]=P19,0)} -> 0 | AA19: {=_xlfn._xlws.FILTER(TablaOpciones[Opcion],TablaOpciones[Planta]=$M$19,0)} -> ALMAGRARIO | AD19: Barranquilla | AE19: {=_xlfn.UNIQUE(TablaOpciones[Planta],FALSE,FALSE)} -> CO01 LN-BC Empresarial | AF19: Traslado | AH19: {=IF(B19="","",IF(SUMPRODUCT((Hoja2!$A$2:$A$121&""=B19&"")*(TRIM(Hoja2!$F$2:$F$121)=TRIM(N19))*(TRIM(Hoja2!$L$2:$L$121)=TRIM(W19)))>0,SUMPRODUCT((Hoja2!$A$2:$A$121&""=B19&"")*(TRIM(Hoja2!$F$2:$F$121)=TRIM(N19))*(TRIM(Hoja2!$L$2:$L$121)=TRIM(W19))*Hoja2!$I$2:$I$121),SUMPRODUCT((Hoja2!$A$2:$A$121&""=B19&"")*(TRIM(Hoja2!$F$2:$F$121)=TRIM(N19))*(Hoja2!$L$2:$L$121="")*Hoja2!$I$2:$I$121)))} | AJ19: CO01 LN-BC Empresarial | AK19: PROMITEL
D20: =IF(ISERROR(VLOOKUP(B20,$A$61:$C$30467,3,FALSE))=TRUE," ",VLOOKUP(B20,$A$61:$C$30467,3,FALSE)) | E20: =IF(ISERROR(VLOOKUP(B20,$A$61:$C$30000,2,FALSE))=TRUE," ",VLOOKUP(B20,$A$61:$C$30000,2,FALSE)) | M20: CO29 LN Villavicencio | AA20: NODO | AD20: Puerto Colombia | AE20: CO02 LN-Steckerl | AH20: {=IF(B20="","",IF(SUMPRODUCT((Hoja2!$A$2:$A$121&""=B20&"")*(TRIM(Hoja2!$F$2:$F$121)=TRIM(N20))*(TRIM(Hoja2!$L$2:$L$121)=TRIM(W20)))>0,SUMPRODUCT((Hoja2!$A$2:$A$121&""=B20&"")*(TRIM(Hoja2!$F$2:$F$121)=TRIM(N20))*(TRIM(Hoja2!$L$2:$L$121)=TRIM(W20))*Hoja2!$I$2:$I$121),SUMPRODUCT((Hoja2!$A$2:$A$121&""=B20&"")*(TRIM(Hoja2!$F$2:$F$121)=TRIM(N20))*(Hoja2!$L$2:$L$121="")*Hoja2!$I$2:$I$121)))} | AJ20: CO01 LN-BC Empresarial | AK20: WOM
D21: =IF(ISERROR(VLOOKUP(B21,$A$61:$C$30467,3,FALSE))=TRUE," ",VLOOKUP(B21,$A$61:$C$30467,3,FALSE)) | E21: =IF(ISERROR(VLOOKUP(B21,$A$61:$C$30000,2,FALSE))=TRUE," ",VLOOKUP(B21,$A$61:$C$30000,2,FALSE)) | M21: CO29 LN Villavicencio | AA21: WOM | AD21: Cartagena | AE21: CO04 LN-Bogota | AH21: {=IF(B21="","",IF(SUMPRODUCT((Hoja2!$A$2:$A$121&""=B21&"")*(TRIM(Hoja2!$F$2:$F$121)=TRIM(N21))*(TRIM(Hoja2!$L$2:$L$121)=TRIM(W21)))>0,SUMPRODUCT((Hoja2!$A$2:$A$121&""=B21&"")*(TRIM(Hoja2!$F$2:$F$121)=TRIM(N21))*(TRIM(Hoja2!$L$2:$L$121)=TRIM(W21))*Hoja2!$I$2:$I$121),SUMPRODUCT((Hoja2!$A$2:$A$121&""=B21&"")*(TRIM(Hoja2!$F$2:$F$121)=TRIM(N21))*(Hoja2!$L$2:$L$121="")*Hoja2!$I$2:$I$121)))} | AJ21: CO02 LN-Steckerl | AK21: STECKERL
D22: =IF(ISERROR(VLOOKUP(B22,$A$61:$C$30467,3,FALSE))=TRUE," ",VLOOKUP(B22,$A$61:$C$30467,3,FALSE)) | E22: =IF(ISERROR(VLOOKUP(B22,$A$61:$C$30000,2,FALSE))=TRUE," ",VLOOKUP(B22,$A$61:$C$30000,2,FALSE)) | M22: CO29 LN Villavicencio | AD22: Cali | AE22: CO03 LN-Bodega Nogales | AH22: {=IF(B22="","",IF(SUMPRODUCT((Hoja2!$A$2:$A$121&""=B22&"")*(TRIM(Hoja2!$F$2:$F$121)=TRIM(N22))*(TRIM(Hoja2!$L$2:$L$121)=TRIM(W22)))>0,SUMPRODUCT((Hoja2!$A$2:$A$121&""=B22&"")*(TRIM(Hoja2!$F$2:$F$121)=TRIM(N22))*(TRIM(Hoja2!$L$2:$L$121)=TRIM(W22))*Hoja2!$I$2:$I$121),SUMPRODUCT((Hoja2!$A$2:$A$121&""=B22&"")*(TRIM(Hoja2!$F$2:$F$121)=TRIM(N22))*(Hoja2!$L$2:$L$121="")*Hoja2!$I$2:$I$121)))} | AJ22: CO04 LN-Bogota | AK22: LN Bogota
D23: =IF(ISERROR(VLOOKUP(B23,$A$61:$C$30467,3,FALSE))=TRUE," ",VLOOKUP(B23,$A$61:$C$30467,3,FALSE)) | E23: =IF(ISERROR(VLOOKUP(B23,$A$61:$C$30000,2,FALSE))=TRUE," ",VLOOKUP(B23,$A$61:$C$30000,2,FALSE)) | M23: CO29 LN Villavicencio | AD23: Bucaramanga | AE23: CO05 LN-Cabecera Bucaramanga | AH23: {=IF(B23="","",IF(SUMPRODUCT((Hoja2!$A$2:$A$121&""=B23&"")*(TRIM(Hoja2!$F$2:$F$121)=TRIM(N23))*(TRIM(Hoja2!$L$2:$L$121)=TRIM(W23)))>0,SUMPRODUCT((Hoja2!$A$2:$A$121&""=B23&"")*(TRIM(Hoja2!$F$2:$F$121)=TRIM(N23))*(TRIM(Hoja2!$L$2:$L$121)=TRIM(W23))*Hoja2!$I$2:$I$121),SUMPRODUCT((Hoja2!$A$2:$A$121&""=B23&"")*(TRIM(Hoja2!$F$2:$F$121)=TRIM(N23))*(Hoja2!$L$2:$L$121="")*Hoja2!$I$2:$I$121)))} | AJ23: CO04 LN-Bogota | AK23: WOM
D24: =IF(ISERROR(VLOOKUP(B24,$A$61:$C$30467,3,FALSE))=TRUE," ",VLOOKUP(B24,$A$61:$C$30467,3,FALSE)) | E24: =IF(ISERROR(VLOOKUP(B24,$A$61:$C$30000,2,FALSE))=TRUE," ",VLOOKUP(B24,$A$61:$C$30000,2,FALSE)) | M24: CO29 LN Villavicencio | AD24: Santa Marta | AE24: CO06 LN-Almagrario Bucaramanga | AH24: {=IF(B24="","",IF(SUMPRODUCT((Hoja2!$A$2:$A$121&""=B24&"")*(TRIM(Hoja2!$F$2:$F$121)=TRIM(N24))*(TRIM(Hoja2!$L$2:$L$121)=TRIM(W24)))>0,SUMPRODUCT((Hoja2!$A$2:$A$121&""=B24&"")*(TRIM(Hoja2!$F$2:$F$121)=TRIM(N24))*(TRIM(Hoja2!$L$2:$L$121)=TRIM(W24))*Hoja2!$I$2:$I$121),SUMPRODUCT((Hoja2!$A$2:$A$121&""=B24&"")*(TRIM(Hoja2!$F$2:$F$121)=TRIM(N24))*(Hoja2!$L$2:$L$121="")*Hoja2!$I$2:$I$121)))} | AJ24: CO04 LN-Bogota | AK24: CN-COLBOG
D25: =IF(ISERROR(VLOOKUP(B25,$A$61:$C$30467,3,FALSE))=TRUE," ",VLOOKUP(B25,$A$61:$C$30467,3,FALSE)) | E25: =IF(ISERROR(VLOOKUP(B25,$A$61:$C$30000,2,FALSE))=TRUE," ",VLOOKUP(B25,$A$61:$C$30000,2,FALSE)) | M25: CO29 LN Villavicencio | AD25: Sincelejo | AE25: CO07 LN-Piedecuesta Bucaramanga | AH25: {=IF(B25="","",IF(SUMPRODUCT((Hoja2!$A$2:$A$121&""=B25&"")*(TRIM(Hoja2!$F$2:$F$121)=TRIM(N25))*(TRIM(Hoja2!$L$2:$L$121)=TRIM(W25)))>0,SUMPRODUCT((Hoja2!$A$2:$A$121&""=B25&"")*(TRIM(Hoja2!$F$2:$F$121)=TRIM(N25))*(TRIM(Hoja2!$L$2:$L$121)=TRIM(W25))*Hoja2!$I$2:$I$121),SUMPRODUCT((Hoja2!$A$2:$A$121&""=B25&"")*(TRIM(Hoja2!$F$2:$F$121)=TRIM(N25))*(Hoja2!$L$2:$L$121="")*Hoja2!$I$2:$I$121)))} | AJ25: CO04 LN-Bogota | AK25: CN-PMBOG
D26: =IF(ISERROR(VLOOKUP(B26,$A$61:$C$30467,3,FALSE))=TRUE," ",VLOOKUP(B26,$A$61:$C$30467,3,FALSE)) | E26: =IF(ISERROR(VLOOKUP(B26,$A$61:$C$30000,2,FALSE))=TRUE," ",VLOOKUP(B26,$A$61:$C$30000,2,FALSE)) | M26: CO29 LN Villavicencio | AD26: Monteria | AE26: CO08 LN-Santa Monica Cali | AH26: {=IF(B26="","",IF(SUMPRODUCT((Hoja2!$A$2:$A$121&""=B26&"")*(TRIM(Hoja2!$F$2:$F$121)=TRIM(N26))*(TRIM(Hoja2!$L$2:$L$121)=TRIM(W26)))>0,SUMPRODUCT((Hoja2!$A$2:$A$121&""=B26&"")*(TRIM(Hoja2!$F$2:$F$121)=TRIM(N26))*(TRIM(Hoja2!$L$2:$L$121)=TRIM(W26))*Hoja2!$I$2:$I$121),SUMPRODUCT((Hoja2!$A$2:$A$121&""=B26&"")*(TRIM(Hoja2!$F$2:$F$121)=TRIM(N26))*(Hoja2!$L$2:$L$121="")*Hoja2!$I$2:$I$121)))} | AJ26: CO04 LN-Bogota | AK26: COLCSC NEW
D27: =IF(ISERROR(VLOOKUP(B27,$A$61:$C$30467,3,FALSE))=TRUE," ",VLOOKUP(B27,$A$61:$C$30467,3,FALSE)) | E27: =IF(ISERROR(VLOOKUP(B27,$A$61:$C$30000,2,FALSE))=TRUE," ",VLOOKUP(B27,$A$61:$C$30000,2,FALSE)) | M27: CO29 LN Villavicencio | Z27: {=_xlfn._xlws.FILTER(TablaOpciones[Opcion],TablaOpciones[Planta]=P20,0)} -> 0 | AA27: {=_xlfn._xlws.FILTER(TablaOpciones[Opcion],TablaOpciones[Planta]=M20,0)} -> ALMAGRARIO | AD27: Popayan | AE27: CO09 LN-Almagrario Cali | AH27: {=IF(B27="","",IF(SUMPRODUCT((Hoja2!$A$2:$A$121&""=B27&"")*(TRIM(Hoja2!$F$2:$F$121)=TRIM(N27))*(TRIM(Hoja2!$L$2:$L$121)=TRIM(W27)))>0,SUMPRODUCT((Hoja2!$A$2:$A$121&""=B27&"")*(TRIM(Hoja2!$F$2:$F$121)=TRIM(N27))*(TRIM(Hoja2!$L$2:$L$121)=TRIM(W27))*Hoja2!$I$2:$I$121),SUMPRODUCT((Hoja2!$A$2:$A$121&""=B27&"")*(TRIM(Hoja2!$F$2:$F$121)=TRIM(N27))*(Hoja2!$L$2:$L$121="")*Hoja2!$I$2:$I$121)))} | AJ27: CO04 LN-Bogota | AK27: CLCSC USED
D28: =IF(ISERROR(VLOOKUP(B28,$A$61:$C$30467,3,FALSE))=TRUE," ",VLOOKUP(B28,$A$61:$C$30467,3,FALSE)) | E28: =IF(ISERROR(VLOOKUP(B28,$A$61:$C$30000,2,FALSE))=TRUE," ",VLOOKUP(B28,$A$61:$C$30000,2,FALSE)) | M28: CO29 LN Villavicencio | AA28: NODO | AD28: Valledupar | AE28: CO10 LN-Almaviva Cartagena | AH28: {=IF(B28="","",IF(SUMPRODUCT((Hoja2!$A$2:$A$121&""=B28&"")*(TRIM(Hoja2!$F$2:$F$121)=TRIM(N28))*(TRIM(Hoja2!$L$2:$L$121)=TRIM(W28)))>0,SUMPRODUCT((Hoja2!$A$2:$A$121&""=B28&"")*(TRIM(Hoja2!$F$2:$F$121)=TRIM(N28))*(TRIM(Hoja2!$L$2:$L$121)=TRIM(W28))*Hoja2!$I$2:$I$121),SUMPRODUCT((Hoja2!$A$2:$A$121&""=B28&"")*(TRIM(Hoja2!$F$2:$F$121)=TRIM(N28))*(Hoja2!$L$2:$L$121="")*Hoja2!$I$2:$I$121)))} | AJ28: CO04 LN-Bogota | AK28: DATACENTER
D29: =IF(ISERROR(VLOOKUP(B29,$A$61:$C$30467,3,FALSE))=TRUE," ",VLOOKUP(B29,$A$61:$C$30467,3,FALSE)) | E29: =IF(ISERROR(VLOOKUP(B29,$A$61:$C$30000,2,FALSE))=TRUE," ",VLOOKUP(B29,$A$61:$C$30000,2,FALSE)) | AA29: WOM | AD29: Bogota | AE29: CO11 LN-Bazurto Cartagena | AH29: {=IF(B29="","",IF(SUMPRODUCT((Hoja2!$A$2:$A$121&""=B29&"")*(TRIM(Hoja2!$F$2:$F$121)=TRIM(N29))*(TRIM(Hoja2!$L$2:$L$121)=TRIM(W29)))>0,SUMPRODUCT((Hoja2!$A$2:$A$121&""=B29&"")*(TRIM(Hoja2!$F$2:$F$121)=TRIM(N29))*(TRIM(Hoja2!$L$2:$L$121)=TRIM(W29))*Hoja2!$I$2:$I$121),SUMPRODUCT((Hoja2!$A$2:$A$121&""=B29&"")*(TRIM(Hoja2!$F$2:$F$121)=TRIM(N29))*(Hoja2!$L$2:$L$121="")*Hoja2!$I$2:$I$121)))} | AJ29: CO04 LN-Bogota | AK29: CFX
D30: =IF(ISERROR(VLOOKUP(B30,$A$61:$C$30467,3,FALSE))=TRUE," ",VLOOKUP(B30,$A$61:$C$30467,3,FALSE)) | E30: =IF(ISERROR(VLOOKUP(B30,$A$61:$C$30000,2,FALSE))=TRUE," ",VLOOKUP(B30,$A$61:$C$30000,2,FALSE)) | AD30: Cucuta | AE30: CO12 LN-CFX Cartagena | AH30: {=IF(B30="","",IF(SUMPRODUCT((Hoja2!$A$2:$A$121&""=B30&"")*(TRIM(Hoja2!$F$2:$F$121)=TRIM(N30))*(TRIM(Hoja2!$L$2:$L$121)=TRIM(W30)))>0,SUMPRODUCT((Hoja2!$A$2:$A$121&""=B30&"")*(TRIM(Hoja2!$F$2:$F$121)=TRIM(N30))*(TRIM(Hoja2!$L$2:$L$121)=TRIM(W30))*Hoja2!$I$2:$I$121),SUMPRODUCT((Hoja2!$A$2:$A$121&""=B30&"")*(TRIM(Hoja2!$F$2:$F$121)=TRIM(N30))*(Hoja2!$L$2:$L$121="")*Hoja2!$I$2:$I$121)))} | AJ30: CO03 LN-Bodega Nogales | AK30: BAJA ROTACION
D31: =IF(ISERROR(VLOOKUP(B31,$A$61:$C$30467,3,FALSE))=TRUE," ",VLOOKUP(B31,$A$61:$C$30467,3,FALSE)) | E31: =IF(ISERROR(VLOOKUP(B31,$A$61:$C$30000,2,FALSE))=TRUE," ",VLOOKUP(B31,$A$61:$C$30000,2,FALSE)) | AD31: Ibague | AE31: CO13 LN-Cucuta | AH31: {=IF(B31="","",IF(SUMPRODUCT((Hoja2!$A$2:$A$121&""=B31&"")*(TRIM(Hoja2!$F$2:$F$121)=TRIM(N31))*(TRIM(Hoja2!$L$2:$L$121)=TRIM(W31)))>0,SUMPRODUCT((Hoja2!$A$2:$A$121&""=B31&"")*(TRIM(Hoja2!$F$2:$F$121)=TRIM(N31))*(TRIM(Hoja2!$L$2:$L$121)=TRIM(W31))*Hoja2!$I$2:$I$121),SUMPRODUCT((Hoja2!$A$2:$A$121&""=B31&"")*(TRIM(Hoja2!$F$2:$F$121)=TRIM(N31))*(Hoja2!$L$2:$L$121="")*Hoja2!$I$2:$I$121)))} | AJ31: CO05 LN-Cabecera Bucaramanga | AK31: CABECERA
D32: =IF(ISERROR(VLOOKUP(B32,$A$61:$C$30467,3,FALSE))=TRUE," ",VLOOKUP(B32,$A$61:$C$30467,3,FALSE)) | E32: =IF(ISERROR(VLOOKUP(B32,$A$61:$C$30000,2,FALSE))=TRUE," ",VLOOKUP(B32,$A$61:$C$30000,2,FALSE)) | AD32: Ibagye | AE32: CO14 LN-ALPOPULAR CUCUTA | AH32: {=IF(B32="","",IF(SUMPRODUCT((Hoja2!$A$2:$A$121&""=B32&"")*(TRIM(Hoja2!$F$2:$F$121)=TRIM(N32))*(TRIM(Hoja2!$L$2:$L$121)=TRIM(W32)))>0,SUMPRODUCT((Hoja2!$A$2:$A$121&""=B32&"")*(TRIM(Hoja2!$F$2:$F$121)=TRIM(N32))*(TRIM(Hoja2!$L$2:$L$121)=TRIM(W32))*Hoja2!$I$2:$I$121),SUMPRODUCT((Hoja2!$A$2:$A$121&""=B32&"")*(TRIM(Hoja2!$F$2:$F$121)=TRIM(N32))*(Hoja2!$L$2:$L$121="")*Hoja2!$I$2:$I$121)))} | AJ32: CO05 LN-Cabecera Bucaramanga | AK32: WOM
D33: =IF(ISERROR(VLOOKUP(B33,$A$61:$C$30467,3,FALSE))=TRUE," ",VLOOKUP(B33,$A$61:$C$30467,3,FALSE)) | E33: =IF(ISERROR(VLOOKUP(B33,$A$61:$C$30000,2,FALSE))=TRUE," ",VLOOKUP(B33,$A$61:$C$30000,2,FALSE)) | AD33: Villavicencio | AE33: CO15 LN Ibague Contratista | AH33: {=IF(B33="","",IF(SUMPRODUCT((Hoja2!$A$2:$A$121&""=B33&"")*(TRIM(Hoja2!$F$2:$F$121)=TRIM(N33))*(TRIM(Hoja2!$L$2:$L$121)=TRIM(W33)))>0,SUMPRODUCT((Hoja2!$A$2:$A$121&""=B33&"")*(TRIM(Hoja2!$F$2:$F$121)=TRIM(N33))*(TRIM(Hoja2!$L$2:$L$121)=TRIM(W33))*Hoja2!$I$2:$I$121),SUMPRODUCT((Hoja2!$A$2:$A$121&""=B33&"")*(TRIM(Hoja2!$F$2:$F$121)=TRIM(N33))*(Hoja2!$L$2:$L$121="")*Hoja2!$I$2:$I$121)))} | AJ33: CO06 LN-Almagrario Bucaramanga | AK33: ALMAGRARIO
D34: =IF(ISERROR(VLOOKUP(B34,$A$61:$C$30467,3,FALSE))=TRUE," ",VLOOKUP(B34,$A$61:$C$30467,3,FALSE)) | E34: =IF(ISERROR(VLOOKUP(B34,$A$61:$C$30000,2,FALSE))=TRUE," ",VLOOKUP(B34,$A$61:$C$30000,2,FALSE)) | AD34: Medellin | AE34: CO16 LN-Ibague | AH34: {=IF(B34="","",IF(SUMPRODUCT((Hoja2!$A$2:$A$121&""=B34&"")*(TRIM(Hoja2!$F$2:$F$121)=TRIM(N34))*(TRIM(Hoja2!$L$2:$L$121)=TRIM(W34)))>0,SUMPRODUCT((Hoja2!$A$2:$A$121&""=B34&"")*(TRIM(Hoja2!$F$2:$F$121)=TRIM(N34))*(TRIM(Hoja2!$L$2:$L$121)=TRIM(W34))*Hoja2!$I$2:$I$121),SUMPRODUCT((Hoja2!$A$2:$A$121&""=B34&"")*(TRIM(Hoja2!$F$2:$F$121)=TRIM(N34))*(Hoja2!$L$2:$L$121="")*Hoja2!$I$2:$I$121)))} | AJ34: CO07 LN-Piedecuesta Bucaramanga | AK34: PIEDECUESTA
D35: =IF(ISERROR(VLOOKUP(B35,$A$61:$C$30467,3,FALSE))=TRUE," ",VLOOKUP(B35,$A$61:$C$30467,3,FALSE)) | E35: =IF(ISERROR(VLOOKUP(B35,$A$61:$C$30000,2,FALSE))=TRUE," ",VLOOKUP(B35,$A$61:$C$30000,2,FALSE)) | Z35: {=_xlfn._xlws.FILTER(TablaOpciones[Opcion],TablaOpciones[Planta]=P21,0)} -> 0 | AA35: {=_xlfn._xlws.FILTER(TablaOpciones[Opcion],TablaOpciones[Planta]=M21,0)} -> ALMAGRARIO | AD35: Pasto | AE35: CO17 LN-Almagrario Medellin | AH35: {=IF(B35="","",IF(SUMPRODUCT((Hoja2!$A$2:$A$121&""=B35&"")*(TRIM(Hoja2!$F$2:$F$121)=TRIM(N35))*(TRIM(Hoja2!$L$2:$L$121)=TRIM(W35)))>0,SUMPRODUCT((Hoja2!$A$2:$A$121&""=B35&"")*(TRIM(Hoja2!$F$2:$F$121)=TRIM(N35))*(TRIM(Hoja2!$L$2:$L$121)=TRIM(W35))*Hoja2!$I$2:$I$121),SUMPRODUCT((Hoja2!$A$2:$A$121&""=B35&"")*(TRIM(Hoja2!$F$2:$F$121)=TRIM(N35))*(Hoja2!$L$2:$L$121="")*Hoja2!$I$2:$I$121)))} | AJ35: CO08 LN-Santa Monica Cali | AK35: Santa Monica
D36: =IF(ISERROR(VLOOKUP(B36,$A$61:$C$30467,3,FALSE))=TRUE," ",VLOOKUP(B36,$A$61:$C$30467,3,FALSE)) | E36: =IF(ISERROR(VLOOKUP(B36,$A$61:$C$30000,2,FALSE))=TRUE," ",VLOOKUP(B36,$A$61:$C$30000,2,FALSE)) | AA36: NODO | AE36: CO18 LN-Nodo Centro Medellin | AH36: {=IF(B36="","",IF(SUMPRODUCT((Hoja2!$A$2:$A$121&""=B36&"")*(TRIM(Hoja2!$F$2:$F$121)=TRIM(N36))*(TRIM(Hoja2!$L$2:$L$121)=TRIM(W36)))>0,SUMPRODUCT((Hoja2!$A$2:$A$121&""=B36&"")*(TRIM(Hoja2!$F$2:$F$121)=TRIM(N36))*(TRIM(Hoja2!$L$2:$L$121)=TRIM(W36))*Hoja2!$I$2:$I$121),SUMPRODUCT((Hoja2!$A$2:$A$121&""=B36&"")*(TRIM(Hoja2!$F$2:$F$121)=TRIM(N36))*(Hoja2!$L$2:$L$121="")*Hoja2!$I$2:$I$121)))} | AJ36: CO08 LN-Santa Monica Cali | AK36: WOM
D37: =IF(ISERROR(VLOOKUP(B37,$A$61:$C$30467,3,FALSE))=TRUE," ",VLOOKUP(B37,$A$61:$C$30467,3,FALSE)) | E37: =IF(ISERROR(VLOOKUP(B37,$A$61:$C$30000,2,FALSE))=TRUE," ",VLOOKUP(B37,$A$61:$C$30000,2,FALSE)) | AA37: WOM | AE37: CO19 LN-Almagrario Monteria | AH37: {=IF(B37="","",IF(SUMPRODUCT((Hoja2!$A$2:$A$121&""=B37&"")*(TRIM(Hoja2!$F$2:$F$121)=TRIM(N37))*(TRIM(Hoja2!$L$2:$L$121)=TRIM(W37)))>0,SUMPRODUCT((Hoja2!$A$2:$A$121&""=B37&"")*(TRIM(Hoja2!$F$2:$F$121)=TRIM(N37))*(TRIM(Hoja2!$L$2:$L$121)=TRIM(W37))*Hoja2!$I$2:$I$121),SUMPRODUCT((Hoja2!$A$2:$A$121&""=B37&"")*(TRIM(Hoja2!$F$2:$F$121)=TRIM(N37))*(Hoja2!$L$2:$L$121="")*Hoja2!$I$2:$I$121)))} | AJ37: CO09 LN-Almagrario Cali | AK37: ALMAGRARIO
D38: =IF(ISERROR(VLOOKUP(B38,$A$61:$C$30467,3,FALSE))=TRUE," ",VLOOKUP(B38,$A$61:$C$30467,3,FALSE)) | E38: =IF(ISERROR(VLOOKUP(B38,$A$61:$C$30000,2,FALSE))=TRUE," ",VLOOKUP(B38,$A$61:$C$30000,2,FALSE)) | AE38: CO20 LN-Nodo Castellana Monteria | AH38: {=IF(B38="","",IF(SUMPRODUCT((Hoja2!$A$2:$A$121&""=B38&"")*(TRIM(Hoja2!$F$2:$F$121)=TRIM(N38))*(TRIM(Hoja2!$L$2:$L$121)=TRIM(W38)))>0,SUMPRODUCT((Hoja2!$A$2:$A$121&""=B38&"")*(TRIM(Hoja2!$F$2:$F$121)=TRIM(N38))*(TRIM(Hoja2!$L$2:$L$121)=TRIM(W38))*Hoja2!$I$2:$I$121),SUMPRODUCT((Hoja2!$A$2:$A$121&""=B38&"")*(TRIM(Hoja2!$F$2:$F$121)=TRIM(N38))*(Hoja2!$L$2:$L$121="")*Hoja2!$I$2:$I$121)))} | AJ38: CO10 LN-Almaviva Cartagena | AK38: Almaviva
AE39: CO21 LN-Pasto | AJ39: CO11 LN-Bazurto Cartagena | AK39: BAZURTO
B40: OBSERVACIONES: | AE40: CO22 LN-Popayan | AJ40: CO11 LN-Bazurto Cartagena | AK40: WOM
AE41: CO23 LN-Nodo Centro Santa Marta | AJ41: CO12 LN-CFX Cartagena | AK41: CFX
AE42: CO24 LN-Deca Santa Marta | AJ42: CO13 LN-Cucuta | AK42: OFICINA
Z43: {=_xlfn._xlws.FILTER(TablaOpciones[Opcion],TablaOpciones[Planta]=P22,0)} -> 0 | AA43: {=_xlfn._xlws.FILTER(TablaOpciones[Opcion],TablaOpciones[Planta]=M22,0)} -> ALMAGRARIO | AE43: CO25 LN-Ocean Mall Santa Marta | AJ43: CO13 LN-Cucuta | AK43: WOM
AA44: NODO | AE44: CO26 LN-Sincelejo | AJ44: CO14 LN-ALPOPULAR CUCUTA | AK44: ALPOPULAR
B45: Solicitado por: | H45: Aprobado por: | AA45: WOM | AE45: CO27 LN-Ingenial Valledupar | AJ45: CO15 LN Ibague Contratista | AK45: BODEGA PE
B46: Fecha: | H46: Fecha: | AE46: CO28 LN-Nodo Centro Valledupar | AJ46: CO16 LN-Ibague | AK46: WOM
AE47: CO29 LN Villavicencio | AJ47: CO16 LN-Ibague | AK47: USADOS
AJ48: CO17 LN-Almagrario Medellin | AK48: ALMAGRARIO
B49: Liberty2025* | AJ49: CO18 LN-Nodo Centro Medellin | AK49: NODO CENTRO
AJ50: CO19 LN-Almagrario Monteria | AK50: ALMAGRARIO
...

Sheet Hoja2
A1: Material | B1: Material Description | C1: Plant | D1: Plant Name | E1: Storage Location | F1: Description of Storage Location | G1: Special Stock Type | H1: Special Stock Type Description | I1: Unrestricted Stock | J1: Stock in Quality Inspection | K1: Blocked Stock | L1: WBS Element
A2: 800376-R | B2: ME3600X/ME3800X DC PWR SUPPLY | C2: CO29 | D2: LN Villavicencio | E2: 0141 | F2: NODO | I2: 2 | J2: 0 | K2: 0 | L2: ZZ.CO11.250130.31
A3: 525397-R | B3: GENCOM NETW / GLC-/ CISCO COMP SFP 100B | C3: CO29 | D3: LN Villavicencio | E3: 0141 | F3: NODO | I3: 3 | J3: 0 | K3: 0 | L3: ZZ.CO11.250130.31
A4: 524164-R | B4: PIGTAL SC/UPC SIMPLEX 1M | C4: CO29 | D4: LN Villavicencio | E4: 0141 | F4: NODO | I4: 13 | J4: 0 | K4: 0 | L4: ZZ.CO11.250130.31
A5: 523600-R | B5: PATCHCORD SC/UPC-SC/UPC 3M SPLX YLLW | C5: CO29 | D5: LN Villavicencio | E5: 0141 | F5: NODO | I5: 2 | J5: 0 | K5: 0 | L5: ZZ.CO11.250130.31
A6: 523272-R | B6: MARQ ELAB EN ACRI POLI CALI 20ES EN SCRE | C6: CO29 | D6: LN Villavicencio | E6: 0141 | F6: NODO | I6: 470 | J6: 0 | K6: 0 | L6: ZZ.CO11.250130.31
A7: 523270-R | B7: MARQ PLAS CBL PMASE PREI | C7: CO29 | D7: LN Villavicencio | E7: 0141 | F7: NODO | I7: 2 | J7: 0 | K7: 0 | L7: ZZ.CO11.250130.31
A8: 523098-R | B8: HERRAJE R 117-128 MM NACIONAL | C8: CO29 | D8: LN Villavicencio | E8: 0140 | F8: ALMAGRARIO | I8: 13 | J8: 0 | K8: 0 | L8: ZZ.CO11.250130.31
A9: 523098-R | B9: HERRAJE R 117-128 MM NACIONAL | C9: CO29 | D9: LN Villavicencio | E9: 0141 | F9: NODO | I9: 44 | J9: 0 | K9: 0 | L9: ZZ.CO11.250130.31
A10: 523042-R | B10: PIGTAIL SC MONOM 3 MTS | C10: CO29 | D10: LN Villavicencio | E10: 0141 | F10: NODO | I10: 1 | J10: 0 | K10: 0 | L10: ZZ.CO11.250130.31
A11: 523040-R | B11: PIGTAIL SC 15 MTS MONOMODO | C11: CO29 | D11: LN Villavicencio | E11: 0141 | F11: NODO | I11: 18 | J11: 0 | K11: 0 | L11: ZZ.CO11.250130.31
A12: 522897-R | B12: CAJA TERMINAL CONECTOR SC/UPC 4-6 HILOS | C12: CO29 | D12: LN Villavicencio | E12: 0141 | F12: NODO | I12: 3 | J12: 0 | K12: 0 | L12: ZZ.CO11.250130.31
A13: 522662-R | B13: CIERRE HERMETICO TYCO 192H | C13: CO29 | D13: LN Villavicencio | E13: 0140 | F13: ALMAGRARIO | I13: 1 | J13: 0 | K13: 0 | L13: ZZ.CO11.250130.31
... A35: 800296 | B35: SFP TRANSC 155M SM SF 1490T/1310R 20K LC | C35: CO29 | D35: LN Villavicencio | E35: 0141 | F35: NODO | I35: 2 | J35: 0 | K35: 0 | L35: ZZ.CO11.250130.31
A36: 800295 | B36: SFP TRANSC 155M SM SF 1310T/1490R 20K LC | C36: CO29 | D36: LN Villavicencio | E36: 0141 | F36: NODO | G36: Q | H36: Project Stock | I36: 3 | J36: 0 | K36: 0 | L36: ZZ.CO11.250212.08
A37: 523272 | B37: MARQ ELAB EN ACRI POLI CALI 20ES EN SCRE | C37: CO29 | D37: LN Villavicencio | E37: 0140 | F37: ALMAGRARIO | I37: 10 | J37: 0 | K37: 0 | L37: ZZ.CO11.250130.31
A38: 523272 | B38: MARQ ELAB EN ACRI POLI CALI 20ES EN SCRE | C38: CO29 | D38: LN Villavicencio | E38: 0141 | F38: NODO | I38: 61 | J38: 0 | K38: 0 | L38: ZZ.CO11.250130.31
A39: 523270 | B39: MARQ PLAS CBL PMASE PREI | C39: CO29 | D39: LN Villavicencio | E39: 0140 | F39: ALMAGRARIO | I39: 5 | J39: 0 | K39: 0 | L39: ZZ.CO11.250130.31
A40: 523120 | B40: ARGOLLA POSTE PARA HERRAJES GPON | C40: CO29 | D40: LN Villavicencio | E40: 0140 | F40: ALMAGRARIO | I40: 270 | J40: 0 | K40: 0 | L40: ZZ.CO11.250130.31
A41: 523119 | B41: HERRAJE DE RETENCION FIBRA PLANA SISCOAX | C41: CO29 | D41: LN Villavicencio | E41: 0140 | F41: ALMAGRARIO | I41: 244 | J41: 0 | K41: 0 | L41: ZZ.CO11.250130.31
A42: 523102 | B42: HERR S FO 12-48 ADSS 90 -110 MM NACI | C42: CO29 | D42: LN Villavicencio | E42: 0141 | F42: NODO | G42: Q | H42: Project Stock | I42: 42 | J42: 0 | K42: 0 | L42: ZZ.CO11.260017.08
A43: 523098 | B43: HERRAJE R 117-128 MM NACIONAL | C43: CO29 | D43: LN Villavicencio | E43: 0141 | F43: NODO | G43: Q | H43: Project Stock | I43: 76 | J43: 0 | K43: 0 | L43: ZZ.CO11.260017.08
A44: 523098 | B44: HERRAJE R 117-128 MM NACIONAL | C44: CO29 | D44: LN Villavicencio | E44: 0141 | F44: NODO | G44: Q | H44: Project Stock | I44: 45 | J44: 0 | K44: 0 | L44: ZZ.CO11.260193.08
A45: 523042 | B45: PIGTAIL SC MONOM 3 MTS | C45: CO29 | D45: LN Villavicencio | E45: 0141 | F45: NODO | I45: 14 | J45: 0 | K45: 0 | L45: ZZ.CO11.250130.31
A46: 523024 | B46: PATCHCORD LC-SC SM 8 MTS DUPLEX | C46: CO29 | D46: LN Villavicencio | E46: 0141 | F46: NODO | I46: 3 | J46: 0 | K46: 0 | L46: ZZ.CO11.250130.31
A47: 523024 | B47: PATCHCORD LC-SC SM 8 MTS DUPLEX | C47: CO29 | D47: LN Villavicencio | E47: 0141 | F47: NODO | G47: Q | H47: Project Stock | I47: 9 | J47: 0 | K47: 0 | L47: ZZ.CO11.260126.31
A48: 523023 | B48: PATCHCORD LC-SC SM 6 MTS DUPLEX | C48: CO29 | D48: LN Villavicencio | E48: 0141 | F48: NODO | G48: Q | H48: Project Stock | I48: 10 | J48: 0 | K48: 0 | L48: ZZ.CO11.260126.31
A49: 523022 | B49: PATCHCORD LC-SC SM 2 MTS DUPLEX | C49: CO29 | D49: LN Villavicencio | E49: 0141 | F49: NODO | G49: Q | H49: Project Stock | I49: 10 | J49: 0 | K49: 0 | L49: ZZ.CO11.260126.31
A50: 523019 | B50: PATCHCORD LC-SC SM 1.5 MTS DUPLEX | C50: CO29 | D50: LN Villavicencio | E50: 0141 | F50: NODO | G50: Q | H50: Project Stock | I50: 8 | J50: 0 | K50: 0 | L50: ZZ.CO11.260126.31
A51: 523017 | B51: PATCHCORD LC-SC SM 5 MTS DUPLEX | C51: CO29 | D51: LN Villavicencio | E51: 0141 | F51: NODO | G51: Q | H51: Project Stock | I51: 10 | J51: 0 | K51: 0 | L51: ZZ.CO11.260126.31
A52: 522969 | B52: PATCHCORD LC-LC SM 10 MTS DUPLEX | C52: CO29 | D52: LN Villavicencio | E52: 0141 | F52: NODO | I52: 5 | J52: 0 | K52: 0 | L52: ZZ.CO11.250130.31
A53: 522966 | B53: PATCHCORD LC-LC SM 8 MTS DUPLEX | C53: CO29 | D53: LN Villavicencio | E53: 0141 | F53: NODO | I53: 5 | J53: 0 | K53: 0 | L53: ZZ.CO11.250130.31
A54: 522965 | B54: PATCHCORD LC-LC SM 5 MTS DUPLEX | C54: CO29 | D54: LN Villavicencio | E54: 0141 | F54: NODO | G54: Q | H54: Project Stock | I54: 5 | J54: 0 | K54: 0 | L54: ZZ.CO11.260126.31
A55: 522963 | B55: PATCHCORD LC-LC SM 3 MTS DUPLEX | C55: CO29 | D55: LN Villavicencio | E55: 0141 | F55: NODO | G55: Q | H55: Project Stock | I55: 5 | J55: 0 | K55: 0 | L55: ZZ.CO11.260126.31
A56: 522962 | B56: PATCHCORD LC-SC SM 3 MTS DUPLEX | C56: CO29 | D56: LN Villavicencio | E56: 0141 | F56: NODO | G56: Q | H56: Project Stock | I56: 10 | J56: 0 | K56: 0 | L56: ZZ.CO11.260126.31
A57: 522958 | B57: PATCHCORD LC-LC SM 1.5 MTS DUPLEX | C57: CO29 | D57: LN Villavicencio | E57: 0141 | F57: NODO | G57: Q | H57: Project Stock | I57: 5 | J57: 0 | K57: 0 | L57: ZZ.CO11.260126.31
A58: 522948 | B58: PATCHCORD SC-SC SM 1.5 MTS DUPLEX | C58: CO29 | D58: LN Villavicencio | E58: 0141 | F58: NODO | G58: Q | H58: Project Stock | I58: 5 | J58: 0 | K58: 0 | L58: ZZ.CO11.260126.31
A59: 522934 | B59: TUBO TERMOCONTRACTIL 45MM | C59: CO29 | D59: LN Villavicencio | E59: 0140 | F59: ALMAGRARIO | I59: 100 | J59: 0 | K59: 0 | L59: ZZ.CO11.250130.31
A60: 522934 | B60: TUBO TERMOCONTRACTIL 45MM | C60: CO29 | D60: LN Villavicencio | E60: 0141 | F60: NODO | I60: 300 | J60: 0 | K60: 0 | L60: ZZ.CO11.250130.31
A61: 522934 | B61: TUBO TERMOCONTRACTIL 45MM | C61: CO29 | D61: LN Villavicencio | E61: 0141 | F61: NODO | G61: Q | H61: Project Stock | I61: 100 | J61: 0 | K61: 0 | L61: ZZ.CO11.260164.31
...

Sheet Hoja1
B3: 302755-R | C3: MERAKI AC PWR CORD F/ MX & MS US PLUG | D3: EA
B4: 302781-R | C4: ASR 9000 4-PORT 100GE LINE CARD REF A9K- | D4: EA
B5: 302786-R | C5: MERAKI MS390 48GE L3 SWT REF MS39 | D5: EA
B6: 302787-R | C6: MERAKI MS390 8X10GE MOD REF MA-M | D6: EA
B7: 302790-R | C7: MERAKI MS42 L3 CLD-16X 10G SFP+ SWIT MS | D7: EA
B8: 302791-R | C8: MERAKI 40GBE QSFP CBL 05 METER REF MA-C | D8: EA
B9: 302803-R | C9: MERAKI 1000BASE SX MULTIMODE | D9: EA
B10: 302804-R | C10: MERAKI MS21 1G L2 CLD-48X GIGE 370W POE | D10: EA
B11: 302852-R | C11: SFP+ 10G-SR OM3 300M OM4 400M STAN TEMP | D11: EA
B12: 302946-R | C12: FORTIAP 221E | D12: EA
B13: 302990-R | C13: FORTIGATE-40F ROUTER REF FG-40F | D13: EA
B14: 304110-R | C14: ASR-9006 CHASSIS ASR-9006-SYS | D14: EA
... B1915: 801761-R | C1915: GABI ALMA DE CABLES OSP- IFC | D1915: EA
